Workbook

Sheet 1. Assumptions & Goals
A1: TIMELINE
A2: Year | B2: 2025 | C2: 2026 | D2: 2027 | E2: 2028 | F2: 2029 | G2: 2030 | H2: 2031 | I2: 2032 | J2: 2033 | K2: 2034 | L2: 2035 | M2: 2036 | N2: 2037 | O2: 2038 | P2: 2039 | Q2: 2040 | R2: 2041 | S2: 2042 | T2: 2043 | U2: 2044 | V2: 2045 | W2: 2046 | X2: 2047 | Y2: 2048 | Z2: 2049 | AA2: 2050 | AB2: 2051 | AC2: 2052 | AD2: 2053 | AE2: 2054 | AF2: 2055 | AG2: 2056 | AH2: 2057 | AI2: 2058 | AJ2: 2059 | AK2: 2060 | AL2: 2061 | AM2: 2062 | AN2: 2063 | AO2: 2064 | AP2: 2065 | AQ2: 2066 | AR2: 2067 | AS2: 2068 | AT2: 2069 | AU2: 2070 | AV2: 2071 | AW2: 2072 | AX2: 2073 | AY2: 2074 | AZ2: 2075 | BA2: 2076 | BB2: 2077 | BC2: 2078 | BD2: 2079 | BE2: 2080 | BF2: 2081 | BG2: 2082 | BH2: 2083 | BI2: 2084 | BJ2: 2085 | BK2: 2086 | BL2: 2087 | BM2: 2088
A3: Age | B3: 22 | C3: 23 | D3: 24 | E3: 25 | F3: 26 | G3: 27 | H3: 28 | I3: 29 | J3: 30 | K3: 31 | L3: 32 | M3: 33 | N3: 34 | O3: 35 | P3: 36 | Q3: 37 | R3: 38 | S3: 39 | T3: 40 | U3: 41 | V3: 42 | W3: 43 | X3: 44 | Y3: 45 | Z3: 46 | AA3: 47 | AB3: 48 | AC3: 49 | AD3: 50 | AE3: 51 | AF3: 52 | AG3: 53 | AH3: 54 | AI3: 55 | AJ3: 56 | AK3: 57 | AL3: 58 | AM3: 59 | AN3: 60 | AO3: 61 | AP3: 62 | AQ3: 63 | AR3: 64 | AS3: 65 | AT3: 66 | AU3: 67 | AV3: 68 | AW3: 69 | AX3: 70 | AY3: 71 | AZ3: 72 | BA3: 73 | BB3: 74 | BC3: 75 | BD3: 76 | BE3: 77 | BF3: 78 | BG3: 79 | BH3: 80 | BI3: 81 | BJ3: 82 | BK3: 83 | BL3: 84 | BM3: 85
A4: Event | H4: Buy car | J4: Nhi's 6 months of maternity leave Buy apartment | K4: Child is born | AC4: Child goes to university | AF4: Child is independent (when year ends) | AN4: Nhi retires (when year ends) | AP4: Husband retires (when year ends) | AY4: Trash car Go travel around the world | BM4: Nhi and Husband die (when year ends)
A6: CUSTOMER PROFILE | F6: FINANCIAL GOALS
B7: Nhi | C7: Husband | F7: Period | G7: Age | H7: Goals
A8: Age | B8: 22 | C8: 22 | F8: Establishing the Foundation for Family | G8: 28 | H8: Buy car around 500 million
A9: Occupation | B9: Financial Analyst | C9: Developer | G9: 30 | H9: Buy an apartment around 4 billion on installments Prepare medical and living expenses for pregnancy
A10: Accommodation | B10: Renting a one-bedroom apartment | F10: Growing the Family and Preparing for the Future | G10: 31 | H10: Give birth to a child, prepare childbirth and initial care costs
A11: Source of income | B11: Salary from employment | G11: 32-52 | H11: Financial support for the child from childhood to independence
A12: Career Timline | B12: Planning to work until retirement | G12: 53 | H12: Prepare marriage cost for the child
A13: Life expectancy | B13: 85 years | F13: Enjoying Life After Retirement | G13: 60 | H13: Nhi retires, enjoy a secure, worry-free retirement
G14: 62 | H14: Husband retires, enjoy a secure, worry-free retirement
A15: ASSUMPTIONS | G15: 71 | H15: Trash car Prepare for travelling around the world, around 5.5 billion for Nhi and Husband
A16: NUMBER | B16: ASSUMPTIONS | C16: BACK-UP REASONS (IF ANY)
A17: 0 | B17: Applicable law used in the model and insurance policy will not change.
A18: Family
A19: 1 | B19: Nhi and Husband are of the same age, marry at 22, get pregnant at 30, live till 85 without any significant health problems.
A20: 2 | B20: Nhi and Husband's parents pay for their marriage, but their parents also take the profit from the wedding gift money. | C20: Marriage Preparation
A21: 3 | B21: After marriage, Nhi and Husband move into the one-room apartment Nhi rents.
A22: 4 | B22: Nhi and Husband have their own phones, laptops, motorbikes and savings account before marriage but decide to combine them as family's assets for easier control.
A23: 5 | B23: Nhi and Husband do not plan to change motorbikes or car. As they carefully maintain, the vehicles are still usable until they die. | C23: Vehicles Longevity
A24: 6 | B24: When Nhi and Husband travel around the world, they ask their child to take care of the home, but still pay for apartment service and other necessary expenses.
A25: Work
A26: 7 | B26: Risk premium with occupational income volatility for Nhi and Husband is 3%.
A27: 8 | B27: Nhi (started as a junior financial analyst) and Husband (started as a junior developer) work for average companies with average abilities, so they receive average salaries for their professions.
A28: 9 | B28: Nhi and Husband's salaries are the salaries after their companies pay for social security and other compulsory obligations for laborers, except taxes. | C28: After-Tax Income
A29: 10 | B29: Nhi and Husband's salaries and expenses increase as inflation rate.
A30: 11 | B30: When Nhi has her maternity leave, Nhi loses her yearly bonus (thirteen-month salary) for that year. | C30: Maternity Leave
A31: Spending
A32: 12 | B32: Fuel and Vehicle Upkeep Expenses already include all compulsory obligations regarding the vehicles (compulsory insurances...).
A33: 13 | B33: Inflation, refinancing rate and other factors (economic, political,...) impacting mortgage rate is fairly stable, it is the same as 2025 when they buy the apartment. Nhi and Husband decide to have an installment of 20 years for the apartment to reduce financial pressure. | C33: 20-year mortgage
A34: 14 | B34: Nhi and Husband have an average spending style, so they spend an average amount compared to the general raising their child. They raise the child until he finishes college, give him money for his marriage and even the wedding gift money.
A35: Saving and Investment
A36: 15 | B36: The Emergency Fund is three times the monthly expenses. | C36: Emergency Fund
A37: Insurance
A38: 16 | B38: Because a 4-seat car can carry up to 5 people (NhaxeHoangDung, n.d.), they buy insurance for 5 people in the car in case they carry people other than their family (friends, colleagues...). | C38: Maximum Carriage
A39: 17 | B39: Inflation, business operation and other factors (economic, political...) impacting the insurance rate and dividend are fairly stable, it is the same as 2025 when they buy life insurance.
A40: 18 | B40: In life insurance calculation, the one who dies has joint properties (apartment, car, bond, stock...) in their name as the worst-case scenario. They also write a will for the surviving spouse to inherit all the joint properties.

Sheet 1. Drivers
A1: ANNUAL TAX INCOME | F1: TAX DEDUCTIONS | J1: DISCOUNT RATE FOR HUMAN CAPITAL AND PENSION VALUE
A2: Tax grade | B2: Taxable income/year (VND million) | C2: Tax rate | D2: Income Tax | F2: Type of deductions | G2: Deduction/month | H2: Tax Deductions | K2: Rate | L2: Risk Free Rate
A3: 1 | B3: Up to 60 | C3: 0.05 | F3: Personal | G3: 11000000 | J3: Risk Free Rate (Vietnam 20-Year Government Bond) | K3: 0.03474
A4: 2 | B4: Between over 60 and 120 | C4: 0.1 | F4: Dependents | G4: 4400000 | J4: Risk premium with occupational income volatility | K4: 0.03
A5: 3 | B5: Between over 120 and 216 | C5: 0.15
A6: 4 | B6: Between over 216 and 384 | C6: 0.2 | F6: AGE OF RETIREMENT
A7: 5 | B7: Between over 384 and 624 | C7: 0.25 | F7: Gender | G7: Age | H7: Retirement
A8: 6 | B8: Between over 624 and 960 | C8: 0.3 | F8: Male | G8: 62
A9: 7 | B9: Over 960 | C9: 0.35 | F9: Female | G9: 60
A11: INFLATION | E11: SAVINGS ACCOUNT INTEREST RATE (2025) | J11: ANNUAL SAVINGS ACCOUNT INTEREST RATE | N11: STOCK MARKET ANNUAL RETURN | R11: BOND INVESTMENT FUND (DCBF) ANNUAL RETURN
A12: Year | B12: Rate | C12: Inflation | E12: Number | F12: Bank | G12: Interest Rate | H12: Interest Rate | J12: Period | K12: Rate | L12: Annual Interest Rate | N12: Year | O12: Return | P12: Stock Return | R12: Date | S12: Price | T12: Return | U12: Bond Return
A13: 2021 | B13: 0.0184 | E13: 1 | F13: BIDV | G13: 0.047 | J13: 2008-2011 | K13: =AVERAGE(9%,14%) -> 0.115 | N13: 2008 | O13: -0.6595 | R13: 44000 | S13: 20036
A14: =A13+1 -> 2022 | B14: 0.0316 | E14: =E13+1 -> 2 | F14: Vietcombank | G14: 0.046 | J14: 2012-2015 | K14: =AVERAGE(6.5%,9%) -> 0.0775 | N14: 2009 | O14: 0.5676 | R14: 44196 | S14: 20756 | T14: =(S14-S13)/S13 -> 0.035935316
A15: =A14+1 -> 2023 | B15: 0.0325 | E15: =E14+1 -> 3 | F15: Agribank | G15: 0.048 | J15: 2016-2019 | K15: =AVERAGE(6%,7%) -> 0.065 | N15: 2010 | O15: -0.0204 | R15: 44350 | S15: 21388 | T15: =(S15-S14)/S14 -> 0.030449027
A16: =A15+1 -> 2024 | B16: 0.0362 | E16: =E15+1 -> 4 | F16: Vietinbank | G16: 0.047 | J16: 2020-2023 | K16: =AVERAGE(4%,6%) -> 0.05 | N16: 2011 | O16: -0.2746 | R16: 44560 | S16: 22270 | T16: =(S16-S15)/S15 -> 0.041238077
A17: 2025 | B17: 0.0295 | E17: =E16+1 -> 5 | F17: VIB | G17: 0.049 | J17: 2024 | K17: =AVERAGE(1.7%,6%) -> 0.0385 | N17: 2012 | O17: 0.1769 | R17: 44714 | S17: 22971 | T17: =(S17-S16)/S16 -> 0.031477324
A18: 2026 | B18: 0.0249 | E18: =E17+1 -> 6 | F18: Techcombank | G18: 0.0475 | J18: 2025 | K18: =G26 -> 0.050346154 | N18: 2013 | O18: 0.2197 | R18: 44923 | S18: 23257 | T18: =(S18-S17)/S17 -> 0.012450481
A19: 2027 | B19: 0.028 | E19: =E18+1 -> 7 | F19: VPBank | G19: 0.053 | J19: Mean | K19: =AVERAGE(K13:K18) -> 0.066057692 | N19: 2014 | O19: 0.0812 | R19: 45084 | S19: 24073 | T19: =(S19-S18)/S18 -> 0.035086211
A20: 2028 | B20: 0.029 | E20: =E19+1 -> 8 | F20: TPBank | G20: 0.052 | J20: Standard Deviation | K20: =STDEV(K13:K18) -> 0.027537331 | N20: 2015 | O20: 0.0612 | R20: 45291 | S20: 25390 | T20: =(S20-S19)/S19 -> 0.054708595
A21: 2029 | B21: 0.029 | E21: =E20+1 -> 9 | F21: ACB | G21: 0.049 | N21: 2016 | O21: 0.1482 | R21: 45449 | S21: 26153 | T21: =(S21-S20)/S20 -> 0.030051201
A22: 2030 | B22: 0.029 | E22: =E21+1 -> 10 | F22: Sacombank | G22: 0.054 | N22: 2017 | O22: 0.4803 | R22: 45610 | S22: 26863 | T22: =(S22-S21)/S21 -> 0.027147937
A23: 2030 Afterwards | B23: =AVERAGE(B13:B22) -> 0.02881 | E23: =E22+1 -> 11 | F23: MSB | G23: 0.056 | N23: 2018 | O23: -0.0932 | R23: Mean | T23: =AVERAGE(T14:T22)*2 -> 0.066343149
E24: =E23+1 -> 12 | F24: HDBank | G24: 0.056 | N24: 2019 | O24: 0.0767 | R24: Standard Deviation | T24: =STDEV(T14:T22)*SQRT(2) -> 0.016014706
E25: =E24+1 -> 13 | F25: MBBank | G25: 0.05 | N25: 2020 | O25: 0.1487
E26: Mean | G26: =AVERAGE(G13:G25) -> 0.050346154 | N26: 2021 | O26: 0.3573
N27: 2022 | O27: -0.3278
N28: 2023 | O28: 0.122
N29: 2024 | O29: 0.1211
N30: Mean | O30: =AVERAGE(O13:O29) -> 0.069729412
N31: Standard Deviation | O31: =STDEV(O13:O29) -> 0.29518767

Sheet 2. Balance Sheet & Cashflow Sta
A1: TRADITIONAL BALANCE SHEET (2025)
A2: ASSETS | B2: AMOUNT | C2: % | F2: LIABILITIES AND NET WORTH | G2: AMOUNT | H2: %
A3: Liquid Assets | F3: Liabilities
A4: Cash | B4: ='3. Funding Allocation'!L5 -> 41955535 | C4: =B4/$B$17 -> 0.17010733 | F4: Short-term Liabilities | G4: 0 | H4: =G4/$G$9 -> 0
A5: Saving Account | B5: 60000000 | C5: =B5/$B$17 -> 0.24326802 | F5: Long-term liabilities | G5: 0 | H5: =G5/$G$9 -> 0
A6: Total Liquid Assets | B6: =SUM(B4:B5) -> 1.0195553e+08 | C6: =B6/$B$17 -> 0.41337535 | F6: Other Liabilities | G6: 0 | H6: =G6/$G$9 -> 0
F7: TOTAL LIABILITIES | G7: =SUM(G4:G6) -> 0 | H7: =G7/$G$9 -> 0
A8: Tangible Assets | F8: NET WORTH | G8: =G9-G7 -> 2.4664154e+08 | H8: =G8/$G$9 -> 1
A9: Samsung Galaxy S23 | B9: 8790000 | C9: =B9/$B$17 -> 0.035638765 | D9: Samsung S23 | F9: TOTAL LIABILITIES AND NET WORTH | G9: =B17 -> 2.4664154e+08 | H9: =G9/$G$9 -> 1
A10: Samsung Galaxy S24 | B10: 11090000 | C10: =B10/$B$17 -> 0.044964039 | D10: Samsung S24
A11: Laptop Dell Inspiron 15 | B11: 11990000 | C11: =B11/$B$17 -> 0.048613059 | D11: Dell Inspiron | F11: RATIO | G11: CALCULATION
A12: Laptop Dell Precision 5550 | B12: 14490000 | C12: =B12/$B$17 -> 0.058749227 | D12: Dell Precision | F12: Solvency Ratio | G12: =G8/B17 -> 1
A13: Honda Vision 2025 (Standard version) | B13: 34735509 | C13: =B13/$B$17 -> 0.14083397 | D13: Vision
A14: Honda Airblade 160 (Standard version) | B14: 63590500 | C14: =B14/$B$17 -> 0.25782558 | D14: Airblade
A15: Total Tangible Assets | B15: =SUM(B9:B14) -> 144686009 | C15: =B15/$B$17 -> 0.58662465
A17: TOTAL ASSETS | B17: =SUM(B6,B15) -> 2.4664154e+08 | C17: =B17/$B$17 -> 1
A19: ECONOMIC (HOLISTIC) BALANCE SHEET (2025)
A20: ASSETS | B20: AMOUNT | C20: % | F20: LIABILITIES AND NET WORTH | G20: AMOUNT | H20: %
A21: Financial Capital | F21: Liabilities
A22: Liquid Assets | B22: =B6 -> 1.0195553e+08 | C22: =B22/$B$36 -> 0.0040010591 | F22: Short-term Liabilities | G22: 0 | H22: =G22/$G$26 -> 0
A23: Tangible Assets | B23: =B15 -> 144686009 | C23: =B23/$B$36 -> 0.0056779387 | F23: Long-term liabilities | G23: 0 | H23: =G23/$G$26 -> 0
A24: Total Financial Capital | B24: =B17 -> 2.4664154e+08 | C24: =B24/$B$36 -> 0.0096789978 | F24: Other Liabilities | G24: 0 | H24: =G24/$G$26 -> 0
F25: Lifetime consumption needs | G25: ='2. Consumption Needs'!B22 -> 2.7200707e+10 | H25: =G25/$G$26 -> 1
A26: Human Capital | F26: TOTAL LIABILITIES | G26: =SUM(G22:G25) -> 2.7200707e+10 | H26: =G26/$G$26 -> 1
A27: Nhi's Human Capital | B27: ='2. Human Capital & Pension Valu'!B19 -> 8.9051492e+09 | C27: =B27/$B$36 -> 0.34946635
A28: Husband's Human Capital | B28: ='2. Human Capital & Pension Valu'!B33 -> 1.0511668e+10 | C28: =B28/$B$36 -> 0.41251126 | F28: ECONOMIC NET WORTH | G28: =B36-G26 -> -1.7185704e+09
A29: Total Human Capital | B29: ='2. Human Capital & Pension Valu'!B35 -> 1.9416817e+10 | C29: =B29/$B$36 -> 0.7619776
A31: Pension Value
A32: Nhi's Pension Value | B32: ='2. Human Capital & Pension Valu'!B48 -> 2.9992074e+09 | C32: =B32/$B$36 -> 0.11769843
A33: Husband's Pension Value | B33: ='2. Human Capital & Pension Valu'!B54 -> 2.8194703e+09 | C33: =B33/$B$36 -> 0.11064497
A34: Total Pension Value | B34: ='2. Human Capital & Pension Valu'!B56 -> 5.8186776e+09 | C34: =B34/$B$36 -> 0.2283434
A36: TOTAL ASSETS | B36: =SUM(B24,B29,B34) -> 2.5482136e+10 | C36: =B36/$B$36 -> 1
A38: CASHFLOW STATEMENT
B39: AMOUNT | C39: %
A40: Income
A41: Nhi's After-tax Income | B41: ='2. Human Capital & Pension Valu'!B17 -> 160975000 | C41: =B41/$B$44 -> 0.43456977
A42: Husband's After-tax Income | B42: ='2. Human Capital & Pension Valu'!B31 -> 203400000 | C42: =B42/$B$44 -> 0.54910074
A43: Interest from Saving Account | B43: ='3. Monte Carlo'!Q2 -> 6048829.3 | C43: =B43/$B$44 -> 0.016329482
A44: Total Income | B44: =SUM(B41:B43) -> 3.7042383e+08 | C44: =B44/$B$44 -> 1
A46: Expenses
...

Sheet 2. Human Capital & Pension Valu
A1: TIMELINE
A2: Year | B2: 2025 | C2: 2026 | D2: 2027 | E2: 2028 | F2: 2029 | G2: 2030 | H2: 2031 | I2: 2032 | J2: 2033 | K2: 2034 | L2: 2035 | M2: 2036 | N2: 2037 | O2: 2038 | P2: 2039 | Q2: 2040 | R2: 2041 | S2: 2042 | T2: 2043 | U2: 2044 | V2: 2045 | W2: 2046 | X2: 2047 | Y2: 2048 | Z2: 2049 | AA2: 2050 | AB2: 2051 | AC2: 2052 | AD2: 2053 | AE2: 2054 | AF2: 2055 | AG2: 2056 | AH2: 2057 | AI2: 2058 | AJ2: 2059 | AK2: 2060 | AL2: 2061 | AM2: 2062 | AN2: 2063 | AO2: 2064 | AP2: 2065 | AQ2: 2066 | AR2: 2067 | AS2: 2068 | AT2: 2069 | AU2: 2070 | AV2: 2071 | AW2: 2072 | AX2: 2073 | AY2: 2074 | AZ2: 2075 | BA2: 2076 | BB2: 2077 | BC2: 2078 | BD2: 2079 | BE2: 2080 | BF2: 2081 | BG2: 2082 | BH2: 2083 | BI2: 2084 | BJ2: 2085 | BK2: 2086 | BL2: 2087 | BM2: 2088
A3: Age | B3: 22 | C3: 23 | D3: 24 | E3: 25 | F3: 26 | G3: 27 | H3: 28 | I3: 29 | J3: 30 | K3: 31 | L3: 32 | M3: 33 | N3: 34 | O3: 35 | P3: 36 | Q3: 37 | R3: 38 | S3: 39 | T3: 40 | U3: 41 | V3: 42 | W3: 43 | X3: 44 | Y3: 45 | Z3: 46 | AA3: 47 | AB3: 48 | AC3: 49 | AD3: 50 | AE3: 51 | AF3: 52 | AG3: 53 | AH3: 54 | AI3: 55 | AJ3: 56 | AK3: 57 | AL3: 58 | AM3: 59 | AN3: 60 | AO3: 61 | AP3: 62 | AQ3: 63 | AR3: 64 | AS3: 65 | AT3: 66 | AU3: 67 | AV3: 68 | AW3: 69 | AX3: 70 | AY3: 71 | AZ3: 72 | BA3: 73 | BB3: 74 | BC3: 75 | BD3: 76 | BE3: 77 | BF3: 78 | BG3: 79 | BH3: 80 | BI3: 81 | BJ3: 82 | BK3: 83 | BL3: 84 | BM3: 85
A4: Event | H4: Buy car | J4: Nhi's 6 months of maternity leave Buy apartment | K4: Child is born | AC4: Child goes to university | AF4: Child is independent (when year ends) | AN4: Nhi retires (when year ends) | AP4: Husband retires (when year ends) | AY4: Trash car Go travel around the world | BM4: Nhi and Husband die (when year ends)
A5: Inflation Rate | B5: ='1. Drivers'!B17 -> 0.0295 | C5: ='1. Drivers'!B18 -> 0.0249 | D5: ='1. Drivers'!B19 -> 0.028 | E5: ='1. Drivers'!B20 -> 0.029 | F5: ='1. Drivers'!B21 -> 0.029 | G5: ='1. Drivers'!B22 -> 0.029 | H5: ='1. Drivers'!$B$23 -> 0.02881 | I5: ='1. Drivers'!$B$23 -> 0.02881 | J5: ='1. Drivers'!$B$23 -> 0.02881 | K5: ='1. Drivers'!$B$23 -> 0.02881 | L5: ='1. Drivers'!$B$23 -> 0.02881 | M5: ='1. Drivers'!$B$23 -> 0.02881 | N5: ='1. Drivers'!$B$23 -> 0.02881 | O5: ='1. Drivers'!$B$23 -> 0.02881 | ... BM5: ='1. Drivers'!$B$23 -> 0.02881
A7: Monthly Salary | B7: Yearly Bonus | C7: Maternity Leave | D7: Surviving Probability
A8: NHI'S HUMAN CAPITAL
A9: Position | B9: Junior Financial Analyst | D9: Senior Financial Analyst | G9: Lead Financial Analyst | O9: Financial Manager | Y9: Financial Director
A10: Monthly Salary | B10: =AVERAGE(10000000,15000000) -> 12500000 | C10: =B10*(1+C5) -> 12811250 | D10: =AVERAGE(15000000,25000000)*(1+C5)*(1+D5) -> 21071944 | E10: =D10*(1+E5) -> 21683030 | F10: =E10*(1+F5) -> 22311838 | G10: =AVERAGE(25000000,40000000)*(1+C5)*(1+D5)*(1+E5)*(1+F5)*(1+G5) -> 37308183 | H10: =G10*(1+H5) -> 38383031 | I10: =H10*(1+I5) -> 39488846 | J10: =I10*(1+J5) -> 40626520 | K10: =J10*(1+K5) -> 41796970 | L10: =K10*(1+L5) -> 43001141 | M10: =L10*(1+M5) -> 44240004 | N10: =M10*(1+N5) -> 45514558 | O10: =AVERAGE(35000000,50000000)*(1+C5)*(1+D5)*(1+E5)*(1+F5)*(1+G5)*(1+H5)^(O2-H2+1) -> 61233781 | P10: =O10*(1+P5) -> 62997926 | Q10: =P10*(1+Q5) -> 64812897 | R10: =Q10*(1+R5) -> 66680156 | S10: =R10*(1+S5) -> 68601211 | T10: =S10*(1+T5) -> 70577612 | U10: =T10*(1+U5) -> 72610953 | V10: =U10*(1+V5) -> 74702875 | W10: =V10*(1+W5) -> 76855065 | X10: =W10*(1+X5) -> 79069259 | Y10: =AVERAGE(50000000,80000000)*(1+C5)*(1+D5)*(1+E5)*(1+F5)*(1+G5)*(1+H5)^(Y2-H2+1) -> 1.2441343e+08 | Z10: =Y10*(1+Z5) -> 1.2799778e+08 | AA10: =Z10*(1+AA5) -> 1.316854e+08 | AB10: =AA10*(1+AB5) -> 1.3547926e+08 | AC10: =AB10*(1+AC5) -> 1.3938241e+08 | AD10: =AC10*(1+AD5) -> 1.4339802e+08 | AE10: =AD10*(1+AE5) -> 1.4752932e+08 | AF10: =AE10*(1+AF5) -> 1.5177964e+08 | AG10: =AF10*(1+AG5) -> 1.5615241e+08 | ... AN10: =AM10*(1+AN5) -> 1.9049998e+08
A11: Yearly Bonus | B11: =B10 -> 12500000 | C11: =C10 -> 12811250 | D11: =D10 -> 21071944 | E11: =E10 -> 21683030 | F11: =F10 -> 22311838 | G11: =G10 -> 37308183 | H11: =H10 -> 38383031 | I11: =I10 -> 39488846 | J11: 0 | K11: =K10 -> 41796970 | L11: =L10 -> 43001141 | M11: =M10 -> 44240004 | N11: =N10 -> 45514558 | O11: =O10 -> 61233781 | P11: =P10 -> 62997926 | Q11: =Q10 -> 64812897 | R11: =R10 -> 66680156 | ... AN11: =AN10 -> 1.9049998e+08
A12: Pretax Annual Salary | B12: =B10*12+B11 -> 162500000 | C12: =C10*12+C11 -> 1.6654625e+08 | D12: =D10*12+D11 -> 273935272 | E12: =E10*12+E11 -> 2.8187939e+08 | F12: =F10*12+F11 -> 2.900539e+08 | G12: =G10*12+G11 -> 4.8500637e+08 | H12: =H10*12+H11 -> 4.9897941e+08 | I12: =I10*12+I11 -> 5.13355e+08 | J12: =J10*6+J11 -> 2.4375912e+08 | K12: =K10*12+K11 -> 5.4336061e+08 | L12: =L10*12+L11 -> 5.5901483e+08 | M12: =M10*12+M11 -> 5.7512005e+08 | N12: =N10*12+N11 -> 5.9168926e+08 | O12: =O10*12+O11 -> 7.9603915e+08 | P12: =P10*12+P11 -> 8.1897304e+08 | Q12: =Q10*12+Q11 -> 8.4256766e+08 | R12: =R10*12+R11 -> 8.6684203e+08 | ... AN12: =AN10*12+AN11 -> 2.4764997e+09
A13: Deductions | B13: =11000000*12 -> 132000000 | C13: =11000000*12 -> 132000000 | D13: =11000000*12 -> 132000000 | E13: =11000000*12 -> 132000000 | F13: =11000000*12 -> 132000000 | G13: =11000000*12 -> 132000000 | H13: =11000000*12 -> 132000000 | I13: =11000000*12 -> 132000000 | ... AN13: =11000000*12 -> 132000000
A14: Assessable Income | B14: =B12-B13 -> 30500000 | C14: =C12-C13 -> 34546250 | D14: =D12-D13 -> 141935272 | E14: =E12-E13 -> 1.4987939e+08 | F14: =F12-F13 -> 1.580539e+08 | G14: =G12-G13 -> 3.5300637e+08 | H14: =H12-H13 -> 3.6697941e+08 | I14: =I12-I13 -> 3.81355e+08 | ... AN14: =AN12-AN13 -> 2.3444997e+09
A15: Income Tax | B15: =IF(B14<=60000000,B14*0.05,IF(B14<=120000000,60000000*0.05+(B14-60000000)*0.1,IF(B14<=216000000,60000000*0.05+60000000*0.1+(B14-120000000)*0.15,IF(B14<=384000000,60000000*0.05+60000000*0.1+96000000*0.15+(B14-216000000)*0.2,IF(B14<=624000000,60000000*0.05+60000000*0.1+96000000*0.15+168000000*0.2+(B14-384000000)*0.25,IF(B14<=960000000,60000000*0.05+60000000*0.1+96000000*0.15+168000000*0.2+240000000*0.25+(B14-624000000)*0.3,60000000*0.05+60000000*0.1+96000000*0.15+168000000*0.2+240000000*0.25+336000000*0.3+(B14-960000000)*0.35)))))) -> 1525000 | C15: =IF(C14<=60000000,C14*0.05,IF(C14<=120000000,60000000*0.05+(C14-60000000)*0.1,IF(C14<=216000000,60000000*0.05+60000000*0.1+(C14-120000000)*0.15,IF(C14<=384000000,60000000*0.05+60000000*0.1+96000000*0.15+(C14-216000000)*0.2,IF(C14<=624000000,60000000*0.05+60000000*0.1+96000000*0.15+168000000*0.2+(C14-384000000)*0.25,IF(C14<=960000000,60000000*0.05+60000000*0.1+96000000*0.15+168000000*0.2+240000000*0.25+(C14-624000000)*0.3,60000000*0.05+60000000*0.1+96000000*0.15+168000000*0.2+240000000*0.25+336000000*0.3+(C14-960000000)*0.35)))))) -> 1727312.5 | D15: =IF(D14<=60000000,D14*0.05,IF(D14<=120000000,60000000*0.05+(D14-60000000)*0.1,IF(D14<=216000000,60000000*0.05+60000000*0.1+(D14-120000000)*0.15,IF(D14<=384000000,60000000*0.05+60000000*0.1+96000000*0.15+(D14-216000000)*0.2,IF(D14<=624000000,60000000*0.05+60000000*0.1+96000000*0.15+168000000*0.2+(D14-384000000)*0.25,IF(D14<=960000000,60000000*0.05+60000000*0.1+96000000*0.15+168000000*0.2+240000000*0.25+(D14-624000000)*0.3,60000000*0.05+60000000*0.1+96000000*0.15+168000000*0.2+240000000*0.25+336000000*0.3+(D14-960000000)*0.35)))))) -> 12290291 | E15: =IF(E14<=60000000,E14*0.05,IF(E14<=120000000,60000000*0.05+(E14-60000000)*0.1,IF(E14<=216000000,60000000*0.05+60000000*0.1+(E14-120000000)*0.15,IF(E14<=384000000,60000000*0.05+60000000*0.1+96000000*0.15+(E14-216000000)*0.2,IF(E14<=624000000,60000000*0.05+60000000*0.1+96000000*0.15+168000000*0.2+(E14-384000000)*0.25,IF(E14<=960000000,60000000*0.05+60000000*0.1+96000000*0.15+168000000*0.2+240000000*0.25+(E14-624000000)*0.3,60000000*0.05+60000000*0.1+96000000*0.15+168000000*0.2+240000000*0.25+336000000*0.3+(E14-960000000)*0.35)))))) -> 13481909 | F15: =IF(F14<=60000000,F14*0.05,IF(F14<=120000000,60000000*0.05+(F14-60000000)*0.1,IF(F14<=216000000,60000000*0.05+60000000*0.1+(F14-120000000)*0.15,IF(F14<=384000000,60000000*0.05+60000000*0.1+96000000*0.15+(F14-216000000)*0.2,IF(F14<=624000000,60000000*0.05+60000000*0.1+96000000*0.15+168000000*0.2+(F14-384000000)*0.25,IF(F14<=960000000,60000000*0.05+60000000*0.1+96000000*0.15+168000000*0.2+240000000*0.25+(F14-624000000)*0.3,60000000*0.05+60000000*0.1+96000000*0.15+168000000*0.2+240000000*0.25+336000000*0.3+(F14-960000000)*0.35)))))) -> 14708085 | G15: =IF(G14<=60000000,G14*0.05,IF(G14<=120000000,60000000*0.05+(G14-60000000)*0.1,IF(G14<=216000000,60000000*0.05+60000000*0.1+(G14-120000000)*0.15,IF(G14<=384000000,60000000*0.05+60000000*0.1+96000000*0.15+(G14-216000000)*0.2,IF(G14<=624000000,60000000*0.05+60000000*0.1+96000000*0.15+168000000*0.2+(G14-384000000)*0.25,IF(G14<=960000000,60000000*0.05+60000000*0.1+96000000*0.15+168000000*0.2+240000000*0.25+(G14-624000000)*0.3,60000000*0.05+60000000*0.1+96000000*0.15+168000000*0.2+240000000*0.25+336000000*0.3+(G14-960000000)*0.35)))))) -> 50801275 | H15: =IF(H14<=60000000,H14*0.05,IF(H14<=120000000,60000000*0.05+(H14-60000000)*0.1,IF(H14<=216000000,60000000*0.05+60000000*0.1+(H14-120000000)*0.15,IF(H14<=384000000,60000000*0.05+60000000*0.1+96000000*0.15+(H14-216000000)*0.2,IF(H14<=624000000,60000000*0.05+60000000*0.1+96000000*0.15+168000000*0.2+(H14-384000000)*0.25,IF(H14<=960000000,60000000*0.05+60000000*0.1+96000000*0.15+168000000*0.2+240000000*0.25+(H14-624000000)*0.3,60000000*0.05+60000000*0.1+96000000*0.15+168000000*0.2+240000000*0.25+336000000*0.3+(H14-960000000)*0.35)))))) -> 53595881 | I15: =IF(I14<=60000000,I14*0.05,IF(I14<=120000000,60000000*0.05+(I14-60000000)*0.1,IF(I14<=216000000,60000000*0.05+60000000*0.1+(I14-120000000)*0.15,IF(I14<=384000000,60000000*0.05+60000000*0.1+96000000*0.15+(I14-216000000)*0.2,IF(I14<=624000000,60000000*0.05+60000000*0.1+96000000*0.15+168000000*0.2+(I14-384000000)*0.25,IF(I14<=960000000,60000000*0.05+60000000*0.1+96000000*0.15+168000000*0.2+240000000*0.25+(I14-624000000)*0.3,60000000*0.05+60000000*0.1+96000000*0.15+168000000*0.2+240000000*0.25+336000000*0.3+(I14-960000000)*0.35)))))) -> 56471001 | ... AN15: =IF(AN14<=60000000,AN14*0.05,IF(AN14<=120000000,60000000*0.05+(AN14-60000000)*0.1,IF(AN14<=216000000,60000000*0.05+60000000*0.1+(AN14-120000000)*0.15,IF(AN14<=384000000,60000000*0.05+60000000*0.1+96000000*0.15+(AN14-216000000)*0.2,IF(AN14<=624000000,60000000*0.05+60000000*0.1+96000000*0.15+168000000*0.2+(AN14-384000000)*0.25,IF(AN14<=960000000,60000000*0.05+60000000*0.1+96000000*0.15+168000000*0.2+240000000*0.25+(AN14-624000000)*0.3,60000000*0.05+60000000*0.1+96000000*0.15+168000000*0.2+240000000*0.25+336000000*0.3+(AN14-960000000)*0.35)))))) -> 7.0237489e+08
A16: After-tax Income | B16: =B12-B15 -> 160975000 | C16: =C12-C15 -> 1.6481894e+08 | D16: =D12-D15 -> 2.6164498e+08 | E16: =E12-E15 -> 2.6839749e+08 | F16: =F12-F15 -> 2.7534581e+08 | G16: =G12-G15 -> 4.342051e+08 | H16: =H12-H15 -> 4.4538353e+08 | I16: =I12-I15 -> 4.56884e+08 | ... AN16: =AN12-AN15 -> 1.7741248e+09
A17: Present Value of Future Income | B17: =B16/(1+'1. Drivers'!$K$3+'1. Drivers'!$K$4)^(B2-2025) -> 160975000 | C17: =C16/(1+'1. Drivers'!$K$3+'1. Drivers'!$K$4)^(C2-2025) -> 1.5479736e+08 | D17: =D16/(1+'1. Drivers'!$K$3+'1. Drivers'!$K$4)^(D2-2025) -> 2.307944e+08 | E17: =E16/(1+'1. Drivers'!$K$3+'1. Drivers'!$K$4)^(E2-2025) -> 2.2235543e+08 | F17: =F16/(1+'1. Drivers'!$K$3+'1. Drivers'!$K$4)^(F2-2025) -> 2.1424179e+08 | G17: =G16/(1+'1. Drivers'!$K$3+'1. Drivers'!$K$4)^(G2-2025) -> 3.1730511e+08 | H17: =H16/(1+'1. Drivers'!$K$3+'1. Drivers'!$K$4)^(H2-2025) -> 3.0568402e+08 | I17: =I16/(1+'1. Drivers'!$K$3+'1. Drivers'!$K$4)^(I2-2025) -> 2.9451062e+08 | ... AN17: =AN16/(1+'1. Drivers'!$K$3+'1. Drivers'!$K$4)^(AN2-2025) -> 1.6357936e+08
A18: Surviving Probability | B18: =1-0.000416227 -> 0.99958377 | C18: =1-0.000416227 -> 0.99958377 | D18: =1-0.000416227 -> 0.99958377 | E18: =1- 0.000472252 -> 0.99952775 | F18: =1- 0.000472252 -> 0.99952775 | G18: =1- 0.000472252 -> 0.99952775 | H18: =1- 0.000472252 -> 0.99952775 | I18: =1- 0.000472252 -> 0.99952775 | J18: =1-0.000615292 -> 0.99938471 | K18: =1-0.000615292 -> 0.99938471 | L18: =1-0.000615292 -> 0.99938471 | M18: =1-0.000615292 -> 0.99938471 | N18: =1-0.000615292 -> 0.99938471 | O18: =1-0.000912829 -> 0.99908717 | P18: =1-0.000912829 -> 0.99908717 | Q18: =1-0.000912829 -> 0.99908717 | R18: =1-0.000912829 -> 0.99908717 | S18: =1-0.000912829 -> 0.99908717 | T18: =1-0.001452051 -> 0.99854795 | U18: =1-0.001452051 -> 0.99854795 | V18: =1-0.001452051 -> 0.99854795 | W18: =1-0.001452051 -> 0.99854795 | X18: =1-0.001452051 -> 0.99854795 | Y18: =1-0.002280473 -> 0.99771953 | Z18: =1-0.002280473 -> 0.99771953 | AA18: =1-0.002280473 -> 0.99771953 | AB18: =1-0.002280473 -> 0.99771953 | AC18: =1-0.002280473 -> 0.99771953 | AD18: =1-0.003585945 -> 0.99641406 | AE18: =1-0.003585945 -> 0.99641406 | AF18: =1-0.003585945 -> 0.99641406 | AG18: =1-0.003585945 -> 0.99641406 | AH18: =1-0.003585945 -> 0.99641406 | AI18: =1-0.005487598 -> 0.9945124 | AJ18: =1-0.005487598 -> 0.9945124 | AK18: =1-0.005487598 -> 0.9945124 | AL18: =1-0.005487598 -> 0.9945124 | AM18: =1-0.005487598 -> 0.9945124 | AN18: =1-0.008891343 -> 0.99110866
A19: HUMAN CAPITAL | B19: =SUMPRODUCT(C17:AN17,C18:AN18) -> 8.9051492e+09
A21: Monthly Salary
A22: HUSBAND'S HUMAN CAPITAL
A23: Position | B23: Junior Developer | E23: Senior Developer | J23: Lead Developer | Q23: Developer Manager | AA23: Developer Director
A24: Monthly Salary | B24: =AVERAGE(8000000,24000000) -> 16000000 | C24: =B24*(1+C5) -> 16398400 | D24: =C24*(1+D5) -> 16857555 | E24: =AVERAGE(20000000,52000000)*(1+C5)*(1+D5)*(1+E5) -> 39029455 | F24: =E24*(1+F5) -> 40161309 | G24: =F24*(1+G5) -> 41325987 | H24: =G24*(1+H5) -> 42516588 | I24: =H24*(1+I5) -> 43741491 | J24: =AVERAGE(36000000,48000000)*(1+C5)*(1+D5)*(1+E5)*(1+F5)*(1+G5)*(1+H5)^(J2-H2+1) -> 52501964 | K24: =J24*(1+K5) -> 54014546 | L24: =K24*(1+L5) -> 55570705 | M24: =L24*(1+M5) -> 57171697 | N24: =M24*(1+N5) -> 58818814 | O24: =N24*(1+O5) -> 60513384 | P24: =O24*(1+P5) -> 62256774 | Q24: =AVERAGE(48000000,72000000)*(1+C5)*(1+D5)*(1+E5)*(1+F5)*(1+G5)*(1+H5)^(Q2-H2+1) -> 91500560 | R24: =Q24*(1+R5) -> 94136691 | S24: =R24*(1+S5) -> 96848769 | T24: =S24*(1+T5) -> 99638982 | U24: =T24*(1+U5) -> 1.0250958e+08 | V24: =U24*(1+V5) -> 1.0546288e+08 | W24: =V24*(1+W5) -> 1.0850127e+08 | X24: =W24*(1+X5) -> 1.1162719e+08 | Y24: =X24*(1+Y5) -> 1.1484317e+08 | ... AP24: =AO24*(1+AP5) -> 1.8612434e+08
A25: Yearly Bonus | B25: =B24 -> 16000000 | C25: =C24 -> 16398400 | D25: =D24 -> 16857555 | E25: =E24 -> 39029455 | F25: =F24 -> 40161309 | G25: =G24 -> 41325987 | H25: =H24 -> 42516588 | I25: =I24 -> 43741491 | ... AP25: =AP24 -> 1.8612434e+08
A26: Pretax Annual Salary | B26: =B24*12+B25 -> 208000000 | C26: =C24*12+C25 -> 2.131792e+08 | D26: =D24*12+D25 -> 2.1914822e+08 | E26: =E24*12+E25 -> 5.0738291e+08 | F26: =F24*12+F25 -> 5.2209702e+08 | G26: =G24*12+G25 -> 5.3723783e+08 | H26: =H24*12+H25 -> 5.5271565e+08 | I26: =I24*12+I25 -> 5.6863939e+08 | ... AP26: =AP24*12+AP25 -> 2.4196164e+09
A27: Deductions | B27: =11000000*12 -> 132000000 | C27: =11000000*12 -> 132000000 | D27: =11000000*12 -> 132000000 | E27: =11000000*12 -> 132000000 | F27: =11000000*12 -> 132000000 | G27: =11000000*12 -> 132000000 | H27: =11000000*12 -> 132000000 | I27: =11000000*12 -> 132000000 | J27: =11000000*12 -> 132000000 | K27: =(11000000+4400000)*12 -> 184800000 | L27: =(11000000+4400000)*12 -> 184800000 | M27: =(11000000+4400000)*12 -> 184800000 | N27: =(11000000+4400000)*12 -> 184800000 | O27: =(11000000+4400000)*12 -> 184800000 | P27: =(11000000+4400000)*12 -> 184800000 | Q27: =(11000000+4400000)*12 -> 184800000 | R27: =(11000000+4400000)*12 -> 184800000 | ... AB27: =(11000000+4400000)*12 -> 184800000 | AC27: =11000000*12 -> 132000000 | AD27: =11000000*12 -> 132000000 | AE27: =11000000*12 -> 132000000 | AF27: =11000000*12 -> 132000000 | AG27: =11000000*12 -> 132000000 | AH27: =11000000*12 -> 132000000 | AI27: =11000000*12 -> 132000000 | AJ27: =11000000*12 -> 132000000 | ... AP27: =11000000*12 -> 132000000
A28: Assessable Income | B28: =B26-B27 -> 76000000 | C28: =C26-C27 -> 81179200 | D28: =D26-D27 -> 87148218 | E28: =E26-E27 -> 3.7538291e+08 | F28: =F26-F27 -> 3.9009702e+08 | G28: =G26-G27 -> 4.0523783e+08 | H28: =H26-H27 -> 4.2071565e+08 | I28: =I26-I27 -> 4.3663939e+08 | ... AP28: =AP26-AP27 -> 2.2876164e+09
A29: Income Tax | B29: =IF(B28<=60000000,B28*0.05,IF(B28<=120000000,60000000*0.05+(B28-60000000)*0.1,IF(B28<=216000000,60000000*0.05+60000000*0.1+(B28-120000000)*0.15,IF(B28<=384000000,60000000*0.05+60000000*0.1+96000000*0.15+(B28-216000000)*0.2,IF(B28<=624000000,60000000*0.05+60000000*0.1+96000000*0.15+168000000*0.2+(B28-384000000)*0.25,IF(B28<=960000000,60000000*0.05+60000000*0.1+96000000*0.15+168000000*0.2+240000000*0.25+(B28-624000000)*0.3,60000000*0.05+60000000*0.1+96000000*0.15+168000000*0.2+240000000*0.25+336000000*0.3+(B28-960000000)*0.35)))))) -> 4600000 | C29: =IF(C28<=60000000,C28*0.05,IF(C28<=120000000,60000000*0.05+(C28-60000000)*0.1,IF(C28<=216000000,60000000*0.05+60000000*0.1+(C28-120000000)*0.15,IF(C28<=384000000,60000000*0.05+60000000*0.1+96000000*0.15+(C28-216000000)*0.2,IF(C28<=624000000,60000000*0.05+60000000*0.1+96000000*0.15+168000000*0.2+(C28-384000000)*0.25,IF(C28<=960000000,60000000*0.05+60000000*0.1+96000000*0.15+168000000*0.2+240000000*0.25+(C28-624000000)*0.3,60000000*0.05+60000000*0.1+96000000*0.15+168000000*0.2+240000000*0.25+336000000*0.3+(C28-960000000)*0.35)))))) -> 5117920 | D29: =IF(D28<=60000000,D28*0.05,IF(D28<=120000000,60000000*0.05+(D28-60000000)*0.1,IF(D28<=216000000,60000000*0.05+60000000*0.1+(D28-120000000)*0.15,IF(D28<=384000000,60000000*0.05+60000000*0.1+96000000*0.15+(D28-216000000)*0.2,IF(D28<=624000000,60000000*0.05+60000000*0.1+96000000*0.15+168000000*0.2+(D28-384000000)*0.25,IF(D28<=960000000,60000000*0.05+60000000*0.1+96000000*0.15+168000000*0.2+240000000*0.25+(D28-624000000)*0.3,60000000*0.05+60000000*0.1+96000000*0.15+168000000*0.2+240000000*0.25+336000000*0.3+(D28-960000000)*0.35)))))) -> 5714821.8 | E29: =IF(E28<=60000000,E28*0.05,IF(E28<=120000000,60000000*0.05+(E28-60000000)*0.1,IF(E28<=216000000,60000000*0.05+60000000*0.1+(E28-120000000)*0.15,IF(E28<=384000000,60000000*0.05+60000000*0.1+96000000*0.15+(E28-216000000)*0.2,IF(E28<=624000000,60000000*0.05+60000000*0.1+96000000*0.15+168000000*0.2+(E28-384000000)*0.25,IF(E28<=960000000,60000000*0.05+60000000*0.1+96000000*0.15+168000000*0.2+240000000*0.25+(E28-624000000)*0.3,60000000*0.05+60000000*0.1+96000000*0.15+168000000*0.2+240000000*0.25+336000000*0.3+(E28-960000000)*0.35)))))) -> 55276582 | F29: =IF(F28<=60000000,F28*0.05,IF(F28<=120000000,60000000*0.05+(F28-60000000)*0.1,IF(F28<=216000000,60000000*0.05+60000000*0.1+(F28-120000000)*0.15,IF(F28<=384000000,60000000*0.05+60000000*0.1+96000000*0.15+(F28-216000000)*0.2,IF(F28<=624000000,60000000*0.05+60000000*0.1+96000000*0.15+168000000*0.2+(F28-384000000)*0.25,IF(F28<=960000000,60000000*0.05+60000000*0.1+96000000*0.15+168000000*0.2+240000000*0.25+(F28-624000000)*0.3,60000000*0.05+60000000*0.1+96000000*0.15+168000000*0.2+240000000*0.25+336000000*0.3+(F28-960000000)*0.35)))))) -> 58524254 | G29: =IF(G28<=60000000,G28*0.05,IF(G28<=120000000,60000000*0.05+(G28-60000000)*0.1,IF(G28<=216000000,60000000*0.05+60000000*0.1+(G28-120000000)*0.15,IF(G28<=384000000,60000000*0.05+60000000*0.1+96000000*0.15+(G28-216000000)*0.2,IF(G28<=624000000,60000000*0.05+60000000*0.1+96000000*0.15+168000000*0.2+(G28-384000000)*0.25,IF(G28<=960000000,60000000*0.05+60000000*0.1+96000000*0.15+168000000*0.2+240000000*0.25+(G28-624000000)*0.3,60000000*0.05+60000000*0.1+96000000*0.15+168000000*0.2+240000000*0.25+336000000*0.3+(G28-960000000)*0.35)))))) -> 62309457 | H29: =IF(H28<=60000000,H28*0.05,IF(H28<=120000000,60000000*0.05+(H28-60000000)*0.1,IF(H28<=216000000,60000000*0.05+60000000*0.1+(H28-120000000)*0.15,IF(H28<=384000000,60000000*0.05+60000000*0.1+96000000*0.15+(H28-216000000)*0.2,IF(H28<=624000000,60000000*0.05+60000000*0.1+96000000*0.15+168000000*0.2+(H28-384000000)*0.25,IF(H28<=960000000,60000000*0.05+60000000*0.1+96000000*0.15+168000000*0.2+240000000*0.25+(H28-624000000)*0.3,60000000*0.05+60000000*0.1+96000000*0.15+168000000*0.2+240000000*0.25+336000000*0.3+(H28-960000000)*0.35)))))) -> 66178913 | I29: =IF(I28<=60000000,I28*0.05,IF(I28<=120000000,60000000*0.05+(I28-60000000)*0.1,IF(I28<=216000000,60000000*0.05+60000000*0.1+(I28-120000000)*0.15,IF(I28<=384000000,60000000*0.05+60000000*0.1+96000000*0.15+(I28-216000000)*0.2,IF(I28<=624000000,60000000*0.05+60000000*0.1+96000000*0.15+168000000*0.2+(I28-384000000)*0.25,IF(I28<=960000000,60000000*0.05+60000000*0.1+96000000*0.15+168000000*0.2+240000000*0.25+(I28-624000000)*0.3,60000000*0.05+60000000*0.1+96000000*0.15+168000000*0.2+240000000*0.25+336000000*0.3+(I28-960000000)*0.35)))))) -> 70159847 | ... AP29: =IF(AP28<=60000000,AP28*0.05,IF(AP28<=120000000,60000000*0.05+(AP28-60000000)*0.1,IF(AP28<=216000000,60000000*0.05+60000000*0.1+(AP28-120000000)*0.15,IF(AP28<=384000000,60000000*0.05+60000000*0.1+96000000*0.15+(AP28-216000000)*0.2,IF(AP28<=624000000,60000000*0.05+60000000*0.1+96000000*0.15+168000000*0.2+(AP28-384000000)*0.25,IF(AP28<=960000000,60000000*0.05+60000000*0.1+96000000*0.15+168000000*0.2+240000000*0.25+(AP28-624000000)*0.3,60000000*0.05+60000000*0.1+96000000*0.15+168000000*0.2+240000000*0.25+336000000*0.3+(AP28-960000000)*0.35)))))) -> 6.8246576e+08
A30: After-tax Income | B30: =B26-B29 -> 203400000 | C30: =C26-C29 -> 2.0806128e+08 | D30: =D26-D29 -> 2.134334e+08 | E30: =E26-E29 -> 4.5210633e+08 | F30: =F26-F29 -> 4.6357276e+08 | G30: =G26-G29 -> 4.7492837e+08 | H30: =H26-H29 -> 4.8653674e+08 | I30: =I26-I29 -> 4.9847954e+08 | ... AP30: =AP26-AP29 -> 1.7371507e+09
A31: Present Value of Future Income | B31: =B30/(1+'1. Drivers'!$K$3+'1. Drivers'!$K$4)^(B2-2025) -> 203400000 | C31: =C30/(1+'1. Drivers'!$K$3+'1. Drivers'!$K$4)^(C2-2025) -> 1.9541041e+08 | D31: =D30/(1+'1. Drivers'!$K$3+'1. Drivers'!$K$4)^(D2-2025) -> 1.8826745e+08 | E31: =E30/(1+'1. Drivers'!$K$3+'1. Drivers'!$K$4)^(E2-2025) -> 3.7455006e+08 | F31: =F30/(1+'1. Drivers'!$K$3+'1. Drivers'!$K$4)^(F2-2025) -> 3.6069791e+08 | G31: =G30/(1+'1. Drivers'!$K$3+'1. Drivers'!$K$4)^(G2-2025) -> 3.4706456e+08 | H31: =H30/(1+'1. Drivers'!$K$3+'1. Drivers'!$K$4)^(H2-2025) -> 3.3392906e+08 | I31: =I30/(1+'1. Drivers'!$K$3+'1. Drivers'!$K$4)^(I2-2025) -> 3.213234e+08 | ... AP31: =AP30/(1+'1. Drivers'!$K$3+'1. Drivers'!$K$4)^(AP2-2025) -> 1.4128456e+08
A32: Surviving Probability | B32: =1-0.00148833 -> 0.99851167 | C32: =1-0.00148833 -> 0.99851167 | D32: =1-0.00148833 -> 0.99851167 | E32: =1-0.001467648 -> 0.99853235 | F32: =1-0.001467648 -> 0.99853235 | G32: =1-0.001467648 -> 0.99853235 | H32: =1-0.001467648 -> 0.99853235 | I32: =1-0.001467648 -> 0.99853235 | J32: =1-0.001691763 -> 0.99830824 | K32: =1-0.001691763 -> 0.99830824 | L32: =1-0.001691763 -> 0.99830824 | M32: =1-0.001691763 -> 0.99830824 | N32: =1-0.001691763 -> 0.99830824 | O32: =1-0.002338274 -> 0.99766173 | P32: =1-0.002338274 -> 0.99766173 | Q32: =1-0.002338274 -> 0.99766173 | R32: =1-0.002338274 -> 0.99766173 | S32: =1-0.002338274 -> 0.99766173 | T32: =1-0.003645446 -> 0.99635455 | U32: =1-0.003645446 -> 0.99635455 | V32: =1-0.003645446 -> 0.99635455 | W32: =1-0.003645446 -> 0.99635455 | X32: =1-0.003645446 -> 0.99635455 | Y32: =1- 0.005916506 -> 0.99408349 | Z32: =1- 0.005916506 -> 0.99408349 | AA32: =1- 0.005916506 -> 0.99408349 | AB32: =1- 0.005916506 -> 0.99408349 | AC32: =1- 0.005916506 -> 0.99408349 | AD32: =1-0.00947506 -> 0.99052494 | AE32: =1-0.00947506 -> 0.99052494 | AF32: =1-0.00947506 -> 0.99052494 | AG32: =1-0.00947506 -> 0.99052494 | AH32: =1-0.00947506 -> 0.99052494 | AI32: =1-0.014665436 -> 0.98533456 | AJ32: =1-0.014665436 -> 0.98533456 | AK32: =1-0.014665436 -> 0.98533456 | AL32: =1-0.014665436 -> 0.98533456 | AM32: =1-0.014665436 -> 0.98533456 | AN32: =1-0.022502985 -> 0.97749701 | AO32: =1-0.022502985 -> 0.97749701 | AP32: =1-0.022502985 -> 0.97749701
A33: HUMAN CAPITAL | B33: =SUMPRODUCT(C31:AP31,C32:AP32) -> 1.0511668e+10
A35: TOTAL HUMAN CAPITAL | B35: =SUM(B19,B33) -> 1.9416817e+10
A38: GENERAL INFORMATION REGARDING PENSION VALUE
B39: Nhi | C39: Husband | D39: Social Security
A40: Year starting Social Security | B40: 45658 | C40: 45658
A41: Average Income | B41: =AVERAGE(B16:AN16) -> 9.171176e+08 | C41: =AVERAGE(B30:AP30) -> 1.0076613e+09
A42: Pension | B42: =75%*B41 -> 6.878382e+08 | C42: =75%*C41 -> 7.5574597e+08
A44: NHI PENSION VALUE
A45: Pension | AO45: =$B$42 -> 6.878382e+08 | AP45: =$B$42 -> 6.878382e+08 | AQ45: =$B$42 -> 6.878382e+08 | AR45: =$B$42 -> 6.878382e+08 | AS45: =$B$42 -> 6.878382e+08 | AT45: =$B$42 -> 6.878382e+08 | AU45: =$B$42 -> 6.878382e+08 | AV45: =$B$42 -> 6.878382e+08 | ... BM45: =$B$42 -> 6.878382e+08
A46: Pension Present Value | AO46: =AO45/(1+'1. Drivers'!$K$3)^(AO2-2025) -> 1.8158e+08 | AP46: =AP45/(1+'1. Drivers'!$K$3)^(AP2-2025) -> 1.754837e+08 | AQ46: =AQ45/(1+'1. Drivers'!$K$3)^(AQ2-2025) -> 1.6959207e+08 | AR46: =AR45/(1+'1. Drivers'!$K$3)^(AR2-2025) -> 1.6389824e+08 | AS46: =AS45/(1+'1. Drivers'!$K$3)^(AS2-2025) -> 1.5839558e+08 | AT46: =AT45/(1+'1. Drivers'!$K$3)^(AT2-2025) -> 1.5307766e+08 | AU46: =AU45/(1+'1. Drivers'!$K$3)^(AU2-2025) -> 1.4793829e+08 | AV46: =AV45/(1+'1. Drivers'!$K$3)^(AV2-2025) -> 1.4297146e+08 | ... BM46: =BM45/(1+'1. Drivers'!$K$3)^(BM2-2025) -> 80005216
...

Sheet 2. Consumption Needs
A1: TIMELINE
A2: Year | B2: 2025 | C2: 2026 | D2: 2027 | E2: 2028 | F2: 2029 | G2: 2030 | H2: 2031 | I2: 2032 | J2: 2033 | K2: 2034 | L2: 2035 | M2: 2036 | N2: 2037 | O2: 2038 | P2: 2039 | Q2: 2040 | R2: 2041 | S2: 2042 | T2: 2043 | U2: 2044 | V2: 2045 | W2: 2046 | X2: 2047 | Y2: 2048 | Z2: 2049 | AA2: 2050 | AB2: 2051 | AC2: 2052 | AD2: 2053 | AE2: 2054 | AF2: 2055 | AG2: 2056 | AH2: 2057 | AI2: 2058 | AJ2: 2059 | AK2: 2060 | AL2: 2061 | AM2: 2062 | AN2: 2063 | AO2: 2064 | AP2: 2065 | AQ2: 2066 | AR2: 2067 | AS2: 2068 | AT2: 2069 | AU2: 2070 | AV2: 2071 | AW2: 2072 | AX2: 2073 | AY2: 2074 | AZ2: 2075 | BA2: 2076 | BB2: 2077 | BC2: 2078 | BD2: 2079 | BE2: 2080 | BF2: 2081 | BG2: 2082 | BH2: 2083 | BI2: 2084 | BJ2: 2085 | BK2: 2086 | BL2: 2087 | BM2: 2088
A3: Age | B3: 22 | C3: 23 | D3: 24 | E3: 25 | F3: 26 | G3: 27 | H3: 28 | I3: 29 | J3: 30 | K3: 31 | L3: 32 | M3: 33 | N3: 34 | O3: 35 | P3: 36 | Q3: 37 | R3: 38 | S3: 39 | T3: 40 | U3: 41 | V3: 42 | W3: 43 | X3: 44 | Y3: 45 | Z3: 46 | AA3: 47 | AB3: 48 | AC3: 49 | AD3: 50 | AE3: 51 | AF3: 52 | AG3: 53 | AH3: 54 | AI3: 55 | AJ3: 56 | AK3: 57 | AL3: 58 | AM3: 59 | AN3: 60 | AO3: 61 | AP3: 62 | AQ3: 63 | AR3: 64 | AS3: 65 | AT3: 66 | AU3: 67 | AV3: 68 | AW3: 69 | AX3: 70 | AY3: 71 | AZ3: 72 | BA3: 73 | BB3: 74 | BC3: 75 | BD3: 76 | BE3: 77 | BF3: 78 | BG3: 79 | BH3: 80 | BI3: 81 | BJ3: 82 | BK3: 83 | BL3: 84 | BM3: 85
A4: Event | H4: Buy car | J4: Nhi's 6 months of maternity leave Buy apartment | K4: Child is born | AC4: Child goes to university | AF4: Child is independent (when year ends) | AN4: Nhi retires (when year ends) | AP4: Husband retires (when year ends) | AY4: Trash car Go travel around the world | BM4: Nhi and Husband die (when year ends)
A5: Inflation Rate | B5: ='1. Drivers'!B17 -> 0.0295 | C5: ='1. Drivers'!B18 -> 0.0249 | D5: ='1. Drivers'!B19 -> 0.028 | E5: ='1. Drivers'!B20 -> 0.029 | F5: ='1. Drivers'!B21 -> 0.029 | G5: ='1. Drivers'!B22 -> 0.029 | H5: ='1. Drivers'!$B$23 -> 0.02881 | I5: ='1. Drivers'!$B$23 -> 0.02881 | J5: ='1. Drivers'!$B$23 -> 0.02881 | K5: ='1. Drivers'!$B$23 -> 0.02881 | L5: ='1. Drivers'!$B$23 -> 0.02881 | M5: ='1. Drivers'!$B$23 -> 0.02881 | N5: ='1. Drivers'!$B$23 -> 0.02881 | O5: ='1. Drivers'!$B$23 -> 0.02881 | ... BM5: ='1. Drivers'!$B$23 -> 0.02881
A7: CONSUMPTION NEED (BEFORE LIFE INSURANCE)
A8: Living Expenses | B8: =B59 -> 3.2545954e+08 | C8: =B8*(1+C5) -> 3.3356349e+08 | D8: =C8*(1+D5) -> 3.4290326e+08 | E8: =D8*(1+E5) -> 3.5284746e+08 | F8: =E8*(1+F5) -> 3.6308004e+08 | G8: =F8*(1+G5) -> 3.7360936e+08 | H8: =G8*(1+H5) -> 3.8437304e+08 | I8: =H8*(1+I5) -> 3.9544683e+08 | J8: =I8*(1+J5) -> 4.0683965e+08 | K8: =(G57+K43)*(1+C5)*(1+D5)*(1+E5)*(1+F5)*(1+G5)*(1+H5)^(K2-H2+1) -> 5.0583863e+08 | L8: =G57*(1+C5)*(1+D5)*(1+E5)*(1+F5)*(1+G5)*(1+H5)^(L2-H2+1) -> 3.6302767e+08 | M8: =L8*(1+M5) -> 3.734865e+08 | N8: =M8*(1+N5) -> 3.8424664e+08 | O8: =N8*(1+O5) -> 3.9531679e+08 | P8: =O8*(1+P5) -> 4.0670587e+08 | Q8: =P8*(1+Q5) -> 4.1842306e+08 | R8: =Q8*(1+R5) -> 4.3047783e+08 | S8: =R8*(1+S5) -> 4.428799e+08 | T8: =S8*(1+T5) -> 4.5563927e+08 | ... AX8: =AW8*(1+AX5) -> 1.0682587e+09 | AY8: =0 -> 0 | AZ8: =AX8*(1+AY5)*(1+AZ5) -> 1.1306985e+09 | BA8: =AZ8*(1+BA5) -> 1.1632739e+09 | BB8: =BA8*(1+BB5) -> 1.1967878e+09 | BC8: =BB8*(1+BC5) -> 1.2312673e+09 | BD8: =BC8*(1+BD5) -> 1.2667401e+09 | BE8: =BD8*(1+BE5) -> 1.3032349e+09 | BF8: =BE8*(1+BF5) -> 1.3407811e+09 | BG8: =BF8*(1+BG5) -> 1.379409e+09 | BH8: =BG8*(1+BH5) -> 1.4191497e+09 | ... BM8: =BL8*(1+BM5) -> 1.6357017e+09
A9: Prenancy and Child Rearing Expenses | J9: =K28*(1+C5)*(1+D5)*(1+E5)*(1+F5)*(1+G5)*(1+H5)^(J2-H2+1) -> 41251543 | K9: =K29*(1+C5)*(1+D5)*(1+E5)*(1+F5)*(1+G5)*(1+H5)^4 -> 60444849 | L9: =K30*(1+C5)*(1+D5)*(1+E5)*(1+F5)*(1+G5)*(1+H5)^5 -> 91294730 | M9: =K30*(1+C5)*(1+D5)*(1+E5)*(1+F5)*(1+G5)*(1+H5)^6 -> 93924931 | N9: =K31*(1+C5)*(1+D5)*(1+E5)*(1+F5)*(1+G5)*(1+H5)^7 -> 70022397 | O9: =K31*(1+C5)*(1+D5)*(1+E5)*(1+F5)*(1+G5)*(1+H5)^8 -> 72039743 | P9: =K31*(1+C5)*(1+D5)*(1+E5)*(1+F5)*(1+G5)*(1+H5)^9 -> 74115207 | Q9: =$K$32*(1+$C$5)*(1+$D$5)*(1+$E$5)*(1+$F$5)*(1+$G$5)*(1+$H$5)^10 -> 37057727 | R9: =$K$32*(1+$C$5)*(1+$D$5)*(1+$E$5)*(1+$F$5)*(1+$G$5)*(1+$H$5)^11 -> 38125360 | S9: =$K$32*(1+$C$5)*(1+$D$5)*(1+$E$5)*(1+$F$5)*(1+$G$5)*(1+$H$5)^12 -> 39223752 | T9: =$K$32*(1+$C$5)*(1+$D$5)*(1+$E$5)*(1+$F$5)*(1+$G$5)*(1+$H$5)^13 -> 40353788 | U9: =$K$32*(1+$C$5)*(1+$D$5)*(1+$E$5)*(1+$F$5)*(1+$G$5)*(1+$H$5)^14 -> 41516380 | V9: =$K$33*(1+$C$5)*(1+$D$5)*(1+$E$5)*(1+$F$5)*(1+$G$5)*(1+$H$5)^15 -> 73384589 | W9: =$K$33*(1+$C$5)*(1+$D$5)*(1+$E$5)*(1+$F$5)*(1+$G$5)*(1+$H$5)^16 -> 75498799 | X9: =$K$33*(1+$C$5)*(1+$D$5)*(1+$E$5)*(1+$F$5)*(1+$G$5)*(1+$H$5)^17 -> 77673919 | Y9: =$K$33*(1+$C$5)*(1+$D$5)*(1+$E$5)*(1+$F$5)*(1+$G$5)*(1+$H$5)^18 -> 79911705 | Z9: =$K$34*(1+$C$5)*(1+$D$5)*(1+$E$5)*(1+$F$5)*(1+$G$5)*(1+$H$5)^19 -> 97147036 | AA9: =$K$34*(1+$C$5)*(1+$D$5)*(1+$E$5)*(1+$F$5)*(1+$G$5)*(1+$H$5)^20 -> 99945842 | AB9: =$K$34*(1+$C$5)*(1+$D$5)*(1+$E$5)*(1+$F$5)*(1+$G$5)*(1+$H$5)^21 -> 1.0282528e+08 | AC9: =($K$35+K36)*(1+$C$5)*(1+$D$5)*(1+$E$5)*(1+$F$5)*(1+$G$5)*(1+$H$5)^22 -> 3.641966e+08 | AD9: =$K$35*(1+$C$5)*(1+$D$5)*(1+$E$5)*(1+$F$5)*(1+$G$5)*(1+$H$5)^23 -> 2.3440061e+08 | AE9: =$K$35*(1+$C$5)*(1+$D$5)*(1+$E$5)*(1+$F$5)*(1+$G$5)*(1+$H$5)^24 -> 2.4115369e+08 | AF9: =$K$35*(1+$C$5)*(1+$D$5)*(1+$E$5)*(1+$F$5)*(1+$G$5)*(1+$H$5)^25 -> 2.4810133e+08 | AG9: =K37*(1+$C$5)*(1+$D$5)*(1+$E$5)*(1+$F$5)*(1+$G$5)*(1+$H$5)^26 -> 3.9182243e+08
A10: Car Expenses | H10: =K50*(1+C5)*(1+D5)*(1+E5)*(1+F5)*(1+G5)*(1+H5) -> 5.6238817e+08 | I10: =(K48+K49)*(1+C5)*(1+D5)*(1+E5)*(1+F5)*(1+G5)*(1+H5)^2 -> 45187391 | J10: =I10*(1+J5) -> 46489239 | K10: =J10*(1+K5) -> 47828594 | L10: =K10*(1+L5) -> 49206536 | M10: =L10*(1+M5) -> 50624177 | N10: =M10*(1+N5) -> 52082659 | O10: =N10*(1+O5) -> 53583160 | P10: =O10*(1+P5) -> 55126891 | Q10: =P10*(1+Q5) -> 56715097 | ... AX10: =AW10*(1+AX5) -> 1.4479698e+08
A11: Apartment (Down Payment and Mortgage Payment) | J11: ='2. Mortgage'!B2-'2. Mortgage'!B4 -> 1.1652075e+09 | K11: ='2. Mortgage'!K2 -> 2.8113427e+08 | L11: ='2. Mortgage'!K14 -> 2.7368177e+08 | M11: ='2. Mortgage'!K26 -> 2.6622927e+08 | N11: ='2. Mortgage'!K38 -> 3.2601865e+08 | O11: ='2. Mortgage'!K50 -> 3.1450115e+08 | P11: ='2. Mortgage'!K62 -> 3.0298365e+08 | Q11: ='2. Mortgage'!K74 -> 2.9146615e+08 | R11: ='2. Mortgage'!K86 -> 2.7994865e+08 | S11: ='2. Mortgage'!K98 -> 2.6843115e+08 | T11: ='2. Mortgage'!K110 -> 2.5691365e+08 | U11: ='2. Mortgage'!K122 -> 2.4539615e+08 | V11: ='2. Mortgage'!K134 -> 2.3387865e+08 | W11: ='2. Mortgage'!K146 -> 2.2236115e+08 | X11: ='2. Mortgage'!K158 -> 2.1084365e+08 | Y11: ='2. Mortgage'!K170 -> 1.9932615e+08 | Z11: ='2. Mortgage'!K182 -> 1.8780865e+08 | AA11: ='2. Mortgage'!K194 -> 1.7629115e+08 | AB11: ='2. Mortgage'!K206 -> 1.6477365e+08 | AC11: ='2. Mortgage'!K218 -> 1.5325615e+08 | AD11: ='2. Mortgage'!K230 -> 1.4173865e+08
A12: Car Insurance | H12: ='4. Health and Car Insurance'!H38 -> 9414583 | I12: ='4. Health and Car Insurance'!I38 -> 9685817.1 | J12: ='4. Health and Car Insurance'!J38 -> 9012148.2 | K12: ='4. Health and Car Insurance'!K38 -> 9271788.2 | L12: ='4. Health and Car Insurance'!L38 -> 9538908.5 | M12: ='4. Health and Car Insurance'!M38 -> 8839786.4 | N12: ='4. Health and Car Insurance'!N38 -> 9094460.7 | O12: ='4. Health and Car Insurance'!O38 -> 9356472.1 | ... AX12: ='4. Health and Car Insurance'!AX38 -> 22962448
A13: Health Insurance | B13: ='4. Health and Car Insurance'!B33 -> 3008750 | C13: ='4. Health and Car Insurance'!C33 -> 3083667.9 | D13: ='4. Health and Car Insurance'!D33 -> 3170010.6 | E13: ='4. Health and Car Insurance'!E33 -> 3261940.9 | F13: ='4. Health and Car Insurance'!F33 -> 3356537.2 | G13: ='4. Health and Car Insurance'!G33 -> 3453876.7 | H13: ='4. Health and Car Insurance'!H33 -> 3553382.9 | I13: ='4. Health and Car Insurance'!I33 -> 3655755.9 | ... AN13: ='4. Health and Car Insurance'!AN33 -> 10581541
A14: Travel Expenses | AY14: =K56*(1+$C$5)*(1+$D$5)*(1+$E$5)*(1+$F$5)*(1+$G$5)*(1+$H$5)^(AY2-H2+1) -> 5.5117493e+09
A15: Total Expenses | B15: =SUM(B8:B14) -> 3.2846829e+08 | C15: =SUM(C8:C14) -> 3.3664715e+08 | D15: =SUM(D8:D14) -> 3.4607328e+08 | E15: =SUM(E8:E14) -> 3.561094e+08 | F15: =SUM(F8:F14) -> 3.6643657e+08 | G15: =SUM(G8:G14) -> 3.7706323e+08 | H15: =SUM(H8:H14) -> 9.5972918e+08 | I15: =SUM(I8:I14) -> 4.5397579e+08 | ... BM15: =SUM(BM8:BM14) -> 1.6357017e+09
A16: Present value of Total Expenses | B16: =B15 -> 3.2846829e+08 | C16: =C15/(1+C5) -> 3.2846829e+08 | D16: =D15/((1+C5)*(1+D5)) -> 3.2846829e+08 | E16: =E15/((1+C5)*(1+D5)*(1+E5)) -> 3.2846829e+08 | F16: =F15/((1+C5)*(1+D5)*(1+E5)*(1+F5)) -> 3.2846829e+08 | G16: =G15/((1+C5)*(1+D5)*(1+E5)*(1+F5)*(1+G5)) -> 3.2846829e+08 | H16: =H15/((1+$C$5)*(1+$D$5)*(1+$E$5)*(1+$F$5)*(1+$G$5)*(1+$H$5)^(H2-$H$2+1)) -> 8.1262989e+08 | I16: =I15/((1+$C$5)*(1+$D$5)*(1+$E$5)*(1+$F$5)*(1+$G$5)*(1+$H$5)^(I2-$H$2+1)) -> 3.7362989e+08 | J16: =J15/((1+$C$5)*(1+$D$5)*(1+$E$5)*(1+$F$5)*(1+$G$5)*(1+$H$5)^(J2-$H$2+1)) -> 1.3379989e+09 | K16: =K15/((1+$C$5)*(1+$D$5)*(1+$E$5)*(1+$F$5)*(1+$G$5)*(1+$H$5)^(K2-$H$2+1)) -> 7.0934215e+08 | L16: =L15/((1+$C$5)*(1+$D$5)*(1+$E$5)*(1+$F$5)*(1+$G$5)*(1+$H$5)^(L2-$H$2+1)) -> 6.0063806e+08 | M16: =M15/((1+$C$5)*(1+$D$5)*(1+$E$5)*(1+$F$5)*(1+$G$5)*(1+$H$5)^(M2-$H$2+1)) -> 5.8865537e+08 | N16: =N15/((1+$C$5)*(1+$D$5)*(1+$E$5)*(1+$F$5)*(1+$G$5)*(1+$H$5)^(N2-$H$2+1)) -> 6.0566804e+08 | O16: =O15/((1+$C$5)*(1+$D$5)*(1+$E$5)*(1+$F$5)*(1+$G$5)*(1+$H$5)^(O2-$H$2+1)) -> 5.9115515e+08 | ... BM16: =BM15/((1+$C$5)*(1+$D$5)*(1+$E$5)*(1+$F$5)*(1+$G$5)*(1+$H$5)^(BM2-$H$2+1)) -> 2.743741e+08
A18: CONSUMPTION NEED (AFTER LIFE INSURANCE)
A19: Life Insurance | L19: ='4. Life Insurance'!B61 -> 8733259.2 | M19: =$L$19 -> 8733259.2 | N19: =$L$19 -> 8733259.2 | O19: =$L$19 -> 8733259.2 | P19: =$L$19 -> 8733259.2 | Q19: =$L$19 -> 8733259.2 | R19: =$L$19 -> 8733259.2 | S19: =$L$19 -> 8733259.2 | T19: =$L$19 -> 8733259.2 | ... AJ19: =$L$19 -> 8733259.2
A20: Total Expenses | B20: =SUM(B8:B14,B19) -> 3.2846829e+08 | C20: =SUM(C8:C14,C19) -> 3.3664715e+08 | D20: =SUM(D8:D14,D19) -> 3.4607328e+08 | E20: =SUM(E8:E14,E19) -> 3.561094e+08 | F20: =SUM(F8:F14,F19) -> 3.6643657e+08 | G20: =SUM(G8:G14,G19) -> 3.7706323e+08 | H20: =SUM(H8:H14,H19) -> 9.5972918e+08 | I20: =SUM(I8:I14,I19) -> 4.5397579e+08 | ... BM20: =SUM(BM8:BM14,BM19) -> 1.6357017e+09
A21: Present value of Total Expenses | B21: =B20 -> 3.2846829e+08 | C21: =C20/(1+C5) -> 3.2846829e+08 | D21: =D20/((1+C5)*(1+D5)) -> 3.2846829e+08 | E21: =E20/((1+C5)*(1+D5)*(1+E5)) -> 3.2846829e+08 | F21: =F20/((1+C5)*(1+D5)*(1+E5)*(1+F5)) -> 3.2846829e+08 | G21: =G20/((1+C5)*(1+D5)*(1+E5)*(1+F5)*(1+G5)) -> 3.2846829e+08 | H21: =H20/((1+$C$5)*(1+$D$5)*(1+$E$5)*(1+$F$5)*(1+$G$5)*(1+$H$5)^(H2-$H$2+1)) -> 8.1262989e+08 | I21: =I20/((1+$C$5)*(1+$D$5)*(1+$E$5)*(1+$F$5)*(1+$G$5)*(1+$H$5)^(I2-$H$2+1)) -> 3.7362989e+08 | J21: =J20/((1+$C$5)*(1+$D$5)*(1+$E$5)*(1+$F$5)*(1+$G$5)*(1+$H$5)^(J2-$H$2+1)) -> 1.3379989e+09 | K21: =K20/((1+$C$5)*(1+$D$5)*(1+$E$5)*(1+$F$5)*(1+$G$5)*(1+$H$5)^(K2-$H$2+1)) -> 7.0934215e+08 | L21: =L20/((1+$C$5)*(1+$D$5)*(1+$E$5)*(1+$F$5)*(1+$G$5)*(1+$H$5)^(L2-$H$2+1)) -> 6.0723861e+08 | M21: =M20/((1+$C$5)*(1+$D$5)*(1+$E$5)*(1+$F$5)*(1+$G$5)*(1+$H$5)^(M2-$H$2+1)) -> 5.9507108e+08 | N21: =N20/((1+$C$5)*(1+$D$5)*(1+$E$5)*(1+$F$5)*(1+$G$5)*(1+$H$5)^(N2-$H$2+1)) -> 6.1190409e+08 | O21: =O20/((1+$C$5)*(1+$D$5)*(1+$E$5)*(1+$F$5)*(1+$G$5)*(1+$H$5)^(O2-$H$2+1)) -> 5.9721657e+08 | ... BM21: =BM20/((1+$C$5)*(1+$D$5)*(1+$E$5)*(1+$F$5)*(1+$G$5)*(1+$H$5)^(BM2-$H$2+1)) -> 2.743741e+08
A22: LIFETIME CONSUMPTION NEEDS | B22: =SUM(B21:BM21) -> 2.7200707e+10
A24: ANNUAL LIVING EXPENSES
A26: BEFORE BUYING HOME | F26: AFTER BUYING HOME | J26: PRENANCY AND CHILD REARING
A27: EXPENSES | B27: AMOUNT/YEAR | C27: % | F27: EXPENSES | G27: AMOUNT/YEAR | H27: % | J27: EXPENSES | K27: AMOUNT/YEAR | L27: %
A28: Rent | B28: =8000000*12 -> 96000000 | C28: =B28/$B$59 -> 0.29496754 | D28: Rent | F28: Utilities | J28: Pregnancy and Childbirth | K28: 33000000 | L28: =K28/$K$38 -> 0.050979121 | M28: Pregnancy
F29: Apartment Service | G29: =AVERAGE(10000,20000)*83*12 -> 14940000 | J29: Aged 0-1 | K29: =AVERAGE(36000000,58000000) -> 47000000 | L29: =K29/$K$38 -> 0.072606627 | M29: Child Rearing
A30: Utilities | F30: Basic (Electricity, Heating, Cooling, Water, Garbage) | G30: =2218015.87*83/85*12 -> 25989927 | H30: =G30/$B$59 -> 0.079856091 | J30: Aged 1-3 | K30: =AVERAGE(116000000,160000000)/2 -> 69000000 | L30: =K30/$K$38 -> 0.10659271
A31: Apartment Service | B31: =AVERAGE(10000,20000)*56*12 -> 10080000 | C31: =B31/$B$59 -> 0.030971591 | D31: Service | F31: Mobile Phone with Calls and 10GB+ Data Monthly | G31: =152500*2*12 -> 3660000 | H31: =G31/$B$59 -> 0.011245637 | J31: Kintergarden (Aged 3-6) | K31: =AVERAGE(126000000,174000000)/3 -> 50000000 | L31: =K31/$K$38 -> 0.077241092
A32: Basic (Electricity, Heating, Cooling, Water, Garbage) | B32: =2218015.87*56/85*12 -> 17535373 | C32: =B32/$B$59 -> 0.053878809 | D32: Utilities | F32: Internet (60 Mbps or More, Unlimited Data, Cable/ADSL) | G32: =246500*12 -> 2958000 | H32: =G32/$B$59 -> 0.0090886872 | J32: Elementary School (Aged 6-11) | K32: =AVERAGE(108000000,135000000)/5 -> 24300000 | L32: =K32/$K$38 -> 0.037539171
A33: Mobile Phone with Calls and 10GB+ Data Monthly | B33: =152500*2*12 -> 3660000 | C33: =B33/$B$59 -> 0.011245637 | F33: Total Utilities | G33: =SUM(G29:G32) -> 47547927 | H33: =G33/$B$59 -> 0.14609474 | J33: Secondary School (Aged 11-15) | K33: =AVERAGE(154000000,180000000)/4 -> 41750000 | L33: =K33/$K$38 -> 0.064496312
A34: Internet (60 Mbps or More, Unlimited Data, Cable/ADSL) | B34: =246500*12 -> 2958000 | C34: =B34/$B$59 -> 0.0090886872 | J34: High School (Aged 15-18) | K34: =AVERAGE(134000000,162000000)/3 -> 49333333 | L34: =K34/$K$38 -> 0.076211211
A35: Total Utilities | B35: =SUM(B31:B34) -> 34233373 | C35: =B35/$B$59 -> 0.10518472 | F35: Foods and Goceries | J35: College (Aged 18-22) | K35: =AVERAGE(350000000,500000000)/4 -> 106250000 | L35: =K35/$K$38 -> 0.16413732
F36: Dine in | G36: =3381090.49*2*12 -> 81146172 | H36: =G36/$B$59 -> 0.24932798 | J36: Honda Airblade 160 (Standard version) | K36: 63590500 | L36: =K36/$K$38 -> 0.098235994
A37: Foods and Goceries | D37: Food | F37: Dine out | G37: =1000000*12 -> 12000000 | H37: =G37/$B$59 -> 0.036870942 | J37: Marriage Support | K37: =7000000+28200000+34200000+(141000000+7400000+39000000)/2 -> 163100000 | L37: =K37/$K$38 -> 0.25196044 | M37: Marriage
A38: Dine in | B38: =3381090.49*2*12 -> 81146172 | C38: =B38/$B$59 -> 0.24932798 | F38: Snacks and Drinks | G38: =500000*12 -> 6000000 | H38: =G38/$B$59 -> 0.018435471 | J38: TOTAL EXPENSES | K38: =SUM(K28:K37) -> 6.4732383e+08 | L38: =K38/$K$38 -> 1
A39: Dine out | B39: =800000*12 -> 9600000 | C39: =B39/$B$59 -> 0.029496754 | F39: Total Foods and Goceries | G39: =SUM(G36:G38) -> 99146172 | H39: =G39/$B$59 -> 0.3046344
A40: Snacks and Drinks | B40: =300000*12 -> 3600000 | C40: =B40/$B$59 -> 0.011061283 | J40: FUNITURE EXPENSE WHEN BUYING HOME
A41: Total Foods and Goceries | B41: =SUM(B38:B40) -> 94346172 | C41: =B41/$B$59 -> 0.28988602 | F41: Transportation | J41: EXPENSES | K41: AMOUNT/YEAR | L41: %
F42: Fuel and Vehicle Upkeep (include Insurance) | G42: =(435000+555000)*12 -> 11880000 | H42: =G42/$B$59 -> 0.036502233 | J42: Interior design & construction | K42: 118950000 | L42: =K42/$K$43 -> 1 | M42: Furnitures
A43: Transportation | F43: Parking Expenses | G43: =AVERAGE(50000,100000)*2*12 -> 1800000 | H43: =G43/$B$59 -> 0.0055306413 | J43: TOTAL EXPENSES | K43: =K42 -> 118950000 | L43: =K43/$K$43 -> 1
A44: Fuel and Vehicle Upkeep | B44: =(435000+555000)*12 -> 11880000 | C44: =B44/$B$59 -> 0.036502233 | D44: Motorbike | F44: Public transport and Taxi | G44: =100000*2*12 -> 2400000 | H44: =G44/$B$59 -> 0.0073741884
...

Sheet 2. Mortgage
A1: Mortgage (BIDV) | E1: Year | F1: Month | G1: Principal payment | H1: Remaining principal | I1: Interest payment | J1: Monthly Total payment | K1: Annually Total payment
A2: Apartment Price | B2: =37350000*83*(1+'1. Drivers'!B18)*(1+'1. Drivers'!B19)*(1+'1. Drivers'!B20)*(1+'1. Drivers'!B21)*(1+'1. Drivers'!B22)*(1+'1. Drivers'!B23)^3 -> 3.8752075e+09 | C2: Home | E2: 2034 | F2: January | G2: =$B$4/(20*12) -> 11291667 | H2: =B4-G2 -> 2.6987083e+09 | I2: =B4*B5/12 -> 12420833 | J2: =SUM(G2,I2) -> 23712500 | K2: =SUM(J2:J13) -> 2.8113427e+08
A3: Max Value can Borrow | B3: =B2*70% -> 2.7126452e+09 | C3: Interest | F3: February | G3: =$B$4/(20*12) -> 11291667 | H3: =H2-G3 -> 2.6874167e+09 | I3: =H2*$B$5/12 -> 12369080 | J3: =SUM(G3,I3) -> 23660747
A4: Principal | B4: =ROUNDDOWN(B3,-7) -> 2710000000 | F4: March | G4: =$B$4/(20*12) -> 11291667 | H4: =H3-G4 -> 2.676125e+09 | I4: =H3*$B$5/12 -> 12317326 | J4: =SUM(G4,I4) -> 23608993
A5: First 3-year | B5: 0.055 | F5: April | G5: =$B$4/(20*12) -> 11291667 | H5: =H4-G5 -> 2.6648333e+09 | I5: =H4*$B$5/12 -> 12265573 | J5: =SUM(G5,I5) -> 23557240
A6: More than 3 years | B6: =B5+3% -> 0.085 | F6: May | G6: =$B$4/(20*12) -> 11291667 | H6: =H5-G6 -> 2.6535417e+09 | I6: =H5*$B$5/12 -> 12213819 | J6: =SUM(G6,I6) -> 23505486
A7: Period | B7: 20 years | F7: June | G7: =$B$4/(20*12) -> 11291667 | H7: =H6-G7 -> 2.64225e+09 | I7: =H6*$B$5/12 -> 12162066 | J7: =SUM(G7,I7) -> 23453733
F8: July | G8: =$B$4/(20*12) -> 11291667 | H8: =H7-G8 -> 2.6309583e+09 | I8: =H7*$B$5/12 -> 12110313 | J8: =SUM(G8,I8) -> 23401979
F9: August | G9: =$B$4/(20*12) -> 11291667 | H9: =H8-G9 -> 2.6196667e+09 | I9: =H8*$B$5/12 -> 12058559 | J9: =SUM(G9,I9) -> 23350226
F10: September | G10: =$B$4/(20*12) -> 11291667 | H10: =H9-G10 -> 2.608375e+09 | I10: =H9*$B$5/12 -> 12006806 | J10: =SUM(G10,I10) -> 23298472
F11: October | G11: =$B$4/(20*12) -> 11291667 | H11: =H10-G11 -> 2.5970833e+09 | I11: =H10*$B$5/12 -> 11955052 | J11: =SUM(G11,I11) -> 23246719
F12: November | G12: =$B$4/(20*12) -> 11291667 | H12: =H11-G12 -> 2.5857917e+09 | I12: =H11*$B$5/12 -> 11903299 | J12: =SUM(G12,I12) -> 23194965
F13: December | G13: =$B$4/(20*12) -> 11291667 | H13: =H12-G13 -> 2.5745e+09 | I13: =H12*$B$5/12 -> 11851545 | J13: =SUM(G13,I13) -> 23143212
E14: 2035 | F14: January | G14: =$B$4/(20*12) -> 11291667 | H14: =H13-G14 -> 2.5632083e+09 | I14: =H13*$B$5/12 -> 11799792 | J14: =SUM(G14,I14) -> 23091458 | K14: =SUM(J14:J25) -> 2.7368177e+08
F15: February | G15: =$B$4/(20*12) -> 11291667 | H15: =H14-G15 -> 2.5519167e+09 | I15: =H14*$B$5/12 -> 11748038 | J15: =SUM(G15,I15) -> 23039705
F16: March | G16: =$B$4/(20*12) -> 11291667 | H16: =H15-G16 -> 2.540625e+09 | I16: =H15*$B$5/12 -> 11696285 | J16: =SUM(G16,I16) -> 22987951
F17: April | G17: =$B$4/(20*12) -> 11291667 | H17: =H16-G17 -> 2.5293333e+09 | I17: =H16*$B$5/12 -> 11644531 | J17: =SUM(G17,I17) -> 22936198
F18: May | G18: =$B$4/(20*12) -> 11291667 | H18: =H17-G18 -> 2.5180417e+09 | I18: =H17*$B$5/12 -> 11592778 | J18: =SUM(G18,I18) -> 22884444
F19: June | G19: =$B$4/(20*12) -> 11291667 | H19: =H18-G19 -> 2.50675e+09 | I19: =H18*$B$5/12 -> 11541024 | J19: =SUM(G19,I19) -> 22832691
F20: July | G20: =$B$4/(20*12) -> 11291667 | H20: =H19-G20 -> 2.4954583e+09 | I20: =H19*$B$5/12 -> 11489271 | J20: =SUM(G20,I20) -> 22780938
F21: August | G21: =$B$4/(20*12) -> 11291667 | H21: =H20-G21 -> 2.4841667e+09 | I21: =H20*$B$5/12 -> 11437517 | J21: =SUM(G21,I21) -> 22729184
F22: September | G22: =$B$4/(20*12) -> 11291667 | H22: =H21-G22 -> 2.472875e+09 | I22: =H21*$B$5/12 -> 11385764 | J22: =SUM(G22,I22) -> 22677431
F23: October | G23: =$B$4/(20*12) -> 11291667 | H23: =H22-G23 -> 2.4615833e+09 | I23: =H22*$B$5/12 -> 11334010 | J23: =SUM(G23,I23) -> 22625677
F24: November | G24: =$B$4/(20*12) -> 11291667 | H24: =H23-G24 -> 2.4502917e+09 | I24: =H23*$B$5/12 -> 11282257 | J24: =SUM(G24,I24) -> 22573924
F25: December | G25: =$B$4/(20*12) -> 11291667 | H25: =H24-G25 -> 2.439e+09 | I25: =H24*$B$5/12 -> 11230503 | J25: =SUM(G25,I25) -> 22522170
E26: 2036 | F26: January | G26: =$B$4/(20*12) -> 11291667 | H26: =H25-G26 -> 2.4277083e+09 | I26: =H25*$B$5/12 -> 11178750 | J26: =SUM(G26,I26) -> 22470417 | K26: =SUM(J26:J37) -> 2.6622927e+08
F27: February | G27: =$B$4/(20*12) -> 11291667 | H27: =H26-G27 -> 2.4164167e+09 | I27: =H26*$B$5/12 -> 11126997 | J27: =SUM(G27,I27) -> 22418663
F28: March | G28: =$B$4/(20*12) -> 11291667 | H28: =H27-G28 -> 2.405125e+09 | I28: =H27*$B$5/12 -> 11075243 | J28: =SUM(G28,I28) -> 22366910
